Workbook

Sheet Overview
C1: Art. No. | D1: product name | E1: amount | F1: PP 1 | G1: PP 2 | H1: PP 3 | I1: PP 4 | J1: PP 5 | K1: PP 6 | Q1: TOTAL ORDER:
B2: Hamm | F2: =IF(E2>=234,(234),(E2)) -> 0 | G2: =IF(E2>=2*234,(234),(E2-F2)) -> 0 | H2: =IF(E2>=3*234,(234),(E2-F2-G2)) -> 0 | I2: =IF(E2>=4*234,(234),(E2-F2-G2-H2)) -> 0 | J2: =IF(E2>=5*234,(234),(E2-F2-G2-H2-I2)) -> 0 | K2: =E2-F2-G2-H2-I2-J2 -> 0 | P2: 322042 | Q2: =SUM(E3,E14,E25,E36) -> 0
C3: 322042 | D3: Pastasalat Mixkarton 4*350g Netto MD | F3: =IF(E3>=120,(120),(E3)) -> 0 | G3: =IF(E3>=2*120,(120),(E3-F3)) -> 0 | H3: =IF(E3>=3*120,(120),(E3-F3-G3)) -> 0 | I3: =IF(E3>=4*120,(120),(E3-F3-G3-H3)) -> 0 | J3: =IF(E3>=5*120,(120),(E3-F3-G3-H3-I3)) -> 0 | K3: =E3-F3-G3-H3-I3-J3 -> 0 | P3: 322029 | Q3: =SUM(E4,E15,E26,E37,E48) -> 0
C4: 322029 | D4: Salatbeutel Mix 1 6er Netto MD | F4: =IF(E4>=120,(120),(E4)) -> 0 | G4: =IF(E4>=2*120,(120),(E4-F4)) -> 0 | H4: =IF(E4>=3*120,(120),(E4-F4-G4)) -> 0 | I4: =IF(E4>=4*120,(120),(E4-F4-G4-H4)) -> 0 | J4: =IF(E4>=5*120,(120),(E4-F4-G4-H4-I4)) -> 0 | K4: =E4-F4-G4-H4-I4-J4 -> 0 | P4: 322030 | Q4: =SUM(E5,E16,E27,E38,E49) -> 0
C5: 322030 | D5: Salatbeutel Mix 2 6er Netto MD | F5: =IF(E5>=120,(120),(E5)) -> 0 | G5: =IF(E5>=2*120,(120),(E5-F5)) -> 0 | H5: =IF(E5>=3*120,(120),(E5-F5-G5)) -> 0 | I5: =IF(E5>=4*120,(120),(E5-F5-G5-H5)) -> 0 | J5: =IF(E5>=5*120,(120),(E5-F5-G5-H5-I5)) -> 0 | K5: =E5-F5-G5-H5-I5-J5 -> 0 | P5: 322041 | Q5: =SUM(E6,E17,E28,E39,E50) -> 0
C6: 322041 | D6: Salatschale Schinken & Käse 4*300g | F6: =IF(E6>=120,(120),(E6)) -> 0 | G6: =IF(E6>=2*120,(120),(E6-F6)) -> 0 | H6: =IF(E6>=3*120,(120),(E6-F6-G6)) -> 0 | I6: =IF(E6>=4*120,(120),(E6-F6-G6-H6)) -> 0 | J6: =IF(E6>=5*120,(120),(E6-F6-G6-H6-I6)) -> 0 | K6: =E6-F6-G6-H6-I6-J6 -> 0 | P6: 322039 | Q6: =SUM(E7,E18,E29,E40,E51) -> 0
C7: 322039 | D7: Salatschale Caesar 4*300g | F7: =IF(E7>=120,(120),(E7)) -> 0 | G7: =IF(E7>=2*120,(120),(E7-F7)) -> 0 | H7: =IF(E7>=3*120,(120),(E7-F7-G7)) -> 0 | I7: =IF(E7>=4*120,(120),(E7-F7-G7-H7)) -> 0 | J7: =IF(E7>=5*120,(120),(E7-F7-G7-H7-I7)) -> 0 | K7: =E7-F7-G7-H7-I7-J7 -> 0 | P7: 322040 | Q7: =SUM(E8,E19,E30,E41,E52) -> 0
C8: 322040 | D8: Salatschale Hänchensalat mit Senf-Dressing 4*300g | F8: =IF(E8>=120,(120),(E8)) -> 0 | G8: =IF(E8>=2*120,(120),(E8-F8)) -> 0 | H8: =IF(E8>=3*120,(120),(E8-F8-G8)) -> 0 | I8: =IF(E8>=4*120,(120),(E8-F8-G8-H8)) -> 0 | J8: =IF(E8>=5*120,(120),(E8-F8-G8-H8-I8)) -> 0 | K8: =E8-F8-G8-H8-I8-J8 -> 0 | P8: 322032 | Q8: =SUM(E9,E20,E31,E42) -> 0
C9: 322032 | D9: Mixkarton Rbg Chin en Ital NETTO 4*400g | F9: =IF(E9>=120,(120),(E9)) -> 0 | G9: =IF(E9>=2*120,(120),(E9-F9)) -> 0 | H9: =IF(E9>=3*120,(120),(E9-F9-G9)) -> 0 | I9: =IF(E9>=4*120,(120),(E9-F9-G9-H9)) -> 0 | J9: =IF(E9>=5*120,(120),(E9-F9-G9-H9-I9)) -> 0 | K9: =E9-F9-G9-H9-I9-J9 -> 0 | P9: 322014 | Q9: =SUM(E52,E62,E72) -> 0
F10: =IF(E10>=120,(120),(E10)) -> 0 | G10: =IF(E10>=2*120,(120),(E10-F10)) -> 0 | H10: =IF(E10>=3*120,(120),(E10-F10-G10)) -> 0 | I10: =IF(E10>=4*120,(120),(E10-F10-G10-H10)) -> 0 | J10: =IF(E10>=5*120,(120),(E10-F10-G10-H10-I10)) -> 0 | K10: =E10-F10-G10-H10-I10-J10 -> 0 | P10: Europallets | Q10: =SUM(C12,C23,C34,C45,C54,C64,C74) -> 0
D11: Europallets | P11: Pallet places | Q11: =SUM(C12,C23,C34,C45,C55,C65,C75) -> 0
D12: Pallet places
B13: Kerpen | F13: =IF(E13>=234,(234),(E13)) -> 0 | G13: =IF(E13>=2*234,(234),(E13-F13)) -> 0 | H13: =IF(E13>=3*234,(234),(E13-F13-G13)) -> 0 | I13: =IF(E13>=4*234,(234),(E13-F13-G13-H13)) -> 0 | J13: =IF(E13>=5*234,(234),(E13-F13-G13-H13-I13)) -> 0 | K13: =E13-F13-G13-H13-I13-J13 -> 0
C14: 322042 | D14: Pastasalat Mixkarton 4*350g Netto MD | F14: =IF(E14>=120,(120),(E14)) -> 0 | G14: =IF(E14>=2*120,(120),(E14-F14)) -> 0 | H14: =IF(E14>=3*120,(120),(E14-F14-G14)) -> 0 | I14: =IF(E14>=4*120,(120),(E14-F14-G14-H14)) -> 0 | J14: =IF(E14>=5*120,(120),(E14-F14-G14-H14-I14)) -> 0 | K14: =E14-F14-G14-H14-I14-J14 -> 0
C15: 322029 | D15: Salatbeutel Mix 1 6er Netto MD | F15: =IF(E15>=120,(120),(E15)) -> 0 | G15: =IF(E15>=2*120,(120),(E15-F15)) -> 0 | H15: =IF(E15>=3*120,(120),(E15-F15-G15)) -> 0 | I15: =IF(E15>=4*120,(120),(E15-F15-G15-H15)) -> 0 | J15: =IF(E15>=5*120,(120),(E15-F15-G15-H15-I15)) -> 0 | K15: =E15-F15-G15-H15-I15-J15 -> 0
C16: 322030 | D16: Salatbeutel Mix 2 6er Netto MD | F16: =IF(E16>=120,(120),(E16)) -> 0 | G16: =IF(E16>=2*120,(120),(E16-F16)) -> 0 | H16: =IF(E16>=3*120,(120),(E16-F16-G16)) -> 0 | I16: =IF(E16>=4*120,(120),(E16-F16-G16-H16)) -> 0 | J16: =IF(E16>=5*120,(120),(E16-F16-G16-H16-I16)) -> 0 | K16: =E16-F16-G16-H16-I16-J16 -> 0
C17: 322041 | D17: Salatschale Schinken & Käse 4*300g | F17: =IF(E17>=120,(120),(E17)) -> 0 | G17: =IF(E17>=2*120,(120),(E17-F17)) -> 0 | H17: =IF(E17>=3*120,(120),(E17-F17-G17)) -> 0 | I17: =IF(E17>=4*120,(120),(E17-F17-G17-H17)) -> 0 | J17: =IF(E17>=5*120,(120),(E17-F17-G17-H17-I17)) -> 0 | K17: =E17-F17-G17-H17-I17-J17 -> 0
C18: 322039 | D18: Salatschale Caesar 4*300g | F18: =IF(E18>=120,(120),(E18)) -> 0 | G18: =IF(E18>=2*120,(120),(E18-F18)) -> 0 | H18: =IF(E18>=3*120,(120),(E18-F18-G18)) -> 0 | I18: =IF(E18>=4*120,(120),(E18-F18-G18-H18)) -> 0 | J18: =IF(E18>=5*120,(120),(E18-F18-G18-H18-I18)) -> 0 | K18: =E18-F18-G18-H18-I18-J18 -> 0
C19: 322040 | D19: Salatschale Hänchensalat mit Senf-Dressing 4*300g | F19: =IF(E19>=120,(120),(E19)) -> 0 | G19: =IF(E19>=2*120,(120),(E19-F19)) -> 0 | H19: =IF(E19>=3*120,(120),(E19-F19-G19)) -> 0 | I19: =IF(E19>=4*120,(120),(E19-F19-G19-H19)) -> 0 | J19: =IF(E19>=5*120,(120),(E19-F19-G19-H19-I19)) -> 0 | K19: =E19-F19-G19-H19-I19-J19 -> 0
C20: 322032 | D20: Mixkarton Rbg Chin en Ital NETTO 4*400g | F20: =IF(E20>=120,(120),(E20)) -> 0 | G20: =IF(E20>=2*120,(120),(E20-F20)) -> 0 | H20: =IF(E20>=3*120,(120),(E20-F20-G20)) -> 0 | I20: =IF(E20>=4*120,(120),(E20-F20-G20-H20)) -> 0 | J20: =IF(E20>=5*120,(120),(E20-F20-G20-H20-I20)) -> 0 | K20: =E20-F20-G20-H20-I20-J20 -> 0
F21: =IF(E21>=120,(120),(E21)) -> 0 | G21: =IF(E21>=2*120,(120),(E21-F21)) -> 0 | H21: =IF(E21>=3*120,(120),(E21-F21-G21)) -> 0 | I21: =IF(E21>=4*120,(120),(E21-F21-G21-H21)) -> 0 | J21: =IF(E21>=5*120,(120),(E21-F21-G21-H21-I21)) -> 0 | K21: =E21-F21-G21-H21-I21-J21 -> 0
D22: Europallets
D23: Pallet places
B24: Bottrop | F24: =IF(E24>=234,(234),(E24)) -> 0 | G24: =IF(E24>=2*234,(234),(E24-F24)) -> 0 | H24: =IF(E24>=3*234,(234),(E24-F24-G24)) -> 0 | I24: =IF(E24>=4*234,(234),(E24-F24-G24-H24)) -> 0 | J24: =IF(E24>=5*234,(234),(E24-F24-G24-H24-I24)) -> 0 | K24: =E24-F24-G24-H24-I24-J24 -> 0
C25: 322042 | D25: Pastasalat Mixkarton 4*350g Netto MD | F25: =IF(E25>=120,(120),(E25)) -> 0 | G25: =IF(E25>=2*120,(120),(E25-F25)) -> 0 | H25: =IF(E25>=3*120,(120),(E25-F25-G25)) -> 0 | I25: =IF(E25>=4*120,(120),(E25-F25-G25-H25)) -> 0 | J25: =IF(E25>=5*120,(120),(E25-F25-G25-H25-I25)) -> 0 | K25: =E25-F25-G25-H25-I25-J25 -> 0
C26: 322029 | D26: Salatbeutel Mix 1 6er Netto MD | F26: =IF(E26>=120,(120),(E26)) -> 0 | G26: =IF(E26>=2*120,(120),(E26-F26)) -> 0 | H26: =IF(E26>=3*120,(120),(E26-F26-G26)) -> 0 | I26: =IF(E26>=4*120,(120),(E26-F26-G26-H26)) -> 0 | J26: =IF(E26>=5*120,(120),(E26-F26-G26-H26-I26)) -> 0 | K26: =E26-F26-G26-H26-I26-J26 -> 0
C27: 322030 | D27: Salatbeutel Mix 2 6er Netto MD | F27: =IF(E27>=120,(120),(E27)) -> 0 | G27: =IF(E27>=2*120,(120),(E27-F27)) -> 0 | H27: =IF(E27>=3*120,(120),(E27-F27-G27)) -> 0 | I27: =IF(E27>=4*120,(120),(E27-F27-G27-H27)) -> 0 | J27: =IF(E27>=5*120,(120),(E27-F27-G27-H27-I27)) -> 0 | K27: =E27-F27-G27-H27-I27-J27 -> 0
C28: 322041 | D28: Salatschale Schinken & Käse 4*300g | F28: =IF(E28>=120,(120),(E28)) -> 0 | G28: =IF(E28>=2*120,(120),(E28-F28)) -> 0 | H28: =IF(E28>=3*120,(120),(E28-F28-G28)) -> 0 | I28: =IF(E28>=4*120,(120),(E28-F28-G28-H28)) -> 0 | J28: =IF(E28>=5*120,(120),(E28-F28-G28-H28-I28)) -> 0 | K28: =E28-F28-G28-H28-I28-J28 -> 0
C29: 322039 | D29: Salatschale Caesar 4*300g | F29: =IF(E29>=120,(120),(E29)) -> 0 | G29: =IF(E29>=2*120,(120),(E29-F29)) -> 0 | H29: =IF(E29>=3*120,(120),(E29-F29-G29)) -> 0 | I29: =IF(E29>=4*120,(120),(E29-F29-G29-H29)) -> 0 | J29: =IF(E29>=5*120,(120),(E29-F29-G29-H29-I29)) -> 0 | K29: =E29-F29-G29-H29-I29-J29 -> 0
C30: 322040 | D30: Salatschale Hänchensalat mit Senf-Dressing 4*300g | F30: =IF(E30>=120,(120),(E30)) -> 0 | G30: =IF(E30>=2*120,(120),(E30-F30)) -> 0 | H30: =IF(E30>=3*120,(120),(E30-F30-G30)) -> 0 | I30: =IF(E30>=4*120,(120),(E30-F30-G30-H30)) -> 0 | J30: =IF(E30>=5*120,(120),(E30-F30-G30-H30-I30)) -> 0 | K30: =E30-F30-G30-H30-I30-J30 -> 0
C31: 322032 | D31: Mixkarton Rbg Chin en Ital NETTO 4*400g | F31: =IF(E31>=120,(120),(E31)) -> 0 | G31: =IF(E31>=2*120,(120),(E31-F31)) -> 0 | H31: =IF(E31>=3*120,(120),(E31-F31-G31)) -> 0 | I31: =IF(E31>=4*120,(120),(E31-F31-G31-H31)) -> 0 | J31: =IF(E31>=5*120,(120),(E31-F31-G31-H31-I31)) -> 0 | K31: =E31-F31-G31-H31-I31-J31 -> 0
F32: =IF(E32>=120,(120),(E32)) -> 0 | G32: =IF(E32>=2*120,(120),(E32-F32)) -> 0 | H32: =IF(E32>=3*120,(120),(E32-F32-G32)) -> 0 | I32: =IF(E32>=4*120,(120),(E32-F32-G32-H32)) -> 0 | J32: =IF(E32>=5*120,(120),(E32-F32-G32-H32-I32)) -> 0 | K32: =E32-F32-G32-H32-I32-J32 -> 0
D33: Europallets
D34: Pallet places
B35: Krefeld | F35: =IF(E35>=234,(234),(E35)) -> 0 | G35: =IF(E35>=2*234,(234),(E35-F35)) -> 0 | H35: =IF(E35>=3*234,(234),(E35-F35-G35)) -> 0 | I35: =IF(E35>=4*234,(234),(E35-F35-G35-H35)) -> 0 | J35: =IF(E35>=5*234,(234),(E35-F35-G35-H35-I35)) -> 0 | K35: =E35-F35-G35-H35-I35-J35 -> 0
C36: 322042 | D36: Pastasalat Mixkarton 4*350g Netto MD | F36: =IF(E36>=120,(120),(E36)) -> 0 | G36: =IF(E36>=2*120,(120),(E36-F36)) -> 0 | H36: =IF(E36>=3*120,(120),(E36-F36-G36)) -> 0 | I36: =IF(E36>=4*120,(120),(E36-F36-G36-H36)) -> 0 | J36: =IF(E36>=5*120,(120),(E36-F36-G36-H36-I36)) -> 0 | K36: =E36-F36-G36-H36-I36-J36 -> 0
C37: 322029 | D37: Salatbeutel Mix 1 6er Netto MD | F37: =IF(E37>=120,(120),(E37)) -> 0 | G37: =IF(E37>=2*120,(120),(E37-F37)) -> 0 | H37: =IF(E37>=3*120,(120),(E37-F37-G37)) -> 0 | I37: =IF(E37>=4*120,(120),(E37-F37-G37-H37)) -> 0 | J37: =IF(E37>=5*120,(120),(E37-F37-G37-H37-I37)) -> 0 | K37: =E37-F37-G37-H37-I37-J37 -> 0
C38: 322030 | D38: Salatbeutel Mix 2 6er Netto MD | F38: =IF(E38>=120,(120),(E38)) -> 0 | G38: =IF(E38>=2*120,(120),(E38-F38)) -> 0 | H38: =IF(E38>=3*120,(120),(E38-F38-G38)) -> 0 | I38: =IF(E38>=4*120,(120),(E38-F38-G38-H38)) -> 0 | J38: =IF(E38>=5*120,(120),(E38-F38-G38-H38-I38)) -> 0 | K38: =E38-F38-G38-H38-I38-J38 -> 0
C39: 322041 | D39: Salatschale Schinken & Käse 4*300g | F39: =IF(E39>=120,(120),(E39)) -> 0 | G39: =IF(E39>=2*120,(120),(E39-F39)) -> 0 | H39: =IF(E39>=3*120,(120),(E39-F39-G39)) -> 0 | I39: =IF(E39>=4*120,(120),(E39-F39-G39-H39)) -> 0 | J39: =IF(E39>=5*120,(120),(E39-F39-G39-H39-I39)) -> 0 | K39: =E39-F39-G39-H39-I39-J39 -> 0
C40: 322039 | D40: Salatschale Caesar 4*300g | F40: =IF(E40>=120,(120),(E40)) -> 0 | G40: =IF(E40>=2*120,(120),(E40-F40)) -> 0 | H40: =IF(E40>=3*120,(120),(E40-F40-G40)) -> 0 | I40: =IF(E40>=4*120,(120),(E40-F40-G40-H40)) -> 0 | J40: =IF(E40>=5*120,(120),(E40-F40-G40-H40-I40)) -> 0 | K40: =E40-F40-G40-H40-I40-J40 -> 0
...

Sheet PROGNOSE EP&PP
B2: =TODAY() -> 46108 | C2: EP | D2: PP
B3: Netto Hamm | C3: =COUNTIF(Overview!F2:K10,"<>0") -> 0 | D3: =ROUNDUP(SUM(Overview!F2:K10)/115,0) -> 0
B4: Netto Kerpen | C4: =COUNTIF(Overview!F13:'Overview'!F13:K21,"<>0") -> 0 | D4: =ROUNDUP(SUM(Overview!F13:K21)/115,0) -> 0
B5: Netto Bottrop | C5: =COUNTIF(Overview!F24:K32,"<>0") -> 0 | D5: =ROUNDUP(SUM(Overview!F24:K32)/115,0) -> 0
B6: Netto Ganderkesee | C6: =COUNTIF(Overview!F46:K52,"<>0") -> 0 | D6: =ROUNDUP(SUM(Overview!F46:K52)/115,0) -> 0
B7: Netto Henstedt-Ulzburg | C7: =COUNTIF(Overview!F57:K63,"<>0") -> 0 | D7: =ROUNDUP(SUM(Overview!F57:K63)/115,0) -> 0
B8: Netto Hodenhagen | C8: =COUNTIF(Overview!F66:K73,"<>0") -> 0 | D8: =ROUNDUP(SUM(Overview!F66:K73)/115,0) -> 0
B9: Netto Krefeld | C9: =COUNTIF(Overview!F35:K43,"<>0") -> 0 | D9: =ROUNDUP(SUM(Overview!F35:K43)/115,0) -> 0
B10: TOTAL: | C10: =SUM(C3:C9) -> 0 | D10: =SUM(D3:D9) -> 0

Sheet MANCOS
D3: STOCK & SALES ORDER AMOUNTS
D5: Article Nr. | E5: Product name | F5: TOTAL ORDER | G5: TOTAL STOCK | H5: MANCO
D6: 322042 | E6: Pastasalat Mixkarton 4*350g Netto MD | F6: =Overview!Q2 -> 0 | G6: =SUMIF($A$14:$A$175,D6,$C$14:$C$175) -> 0 | H6: =IF((G6-F6) > 0, 0,G6-F6) -> 0
D7: 322029 | E7: Salatbeutel Mix 1 6er Netto MD | F7: =Overview!Q3 -> 0 | G7: =SUMIF($A$14:$A$175,D7,$C$14:$C$175) -> 0 | H7: =IF((G7-F7) > 0, 0,G7-F7) -> 0
D8: 322030 | E8: Salatbeutel Mix 2 6er Netto MD | F8: =Overview!Q4 -> 0 | G8: =SUMIF($A$14:$A$175,D8,$C$14:$C$175) -> 0 | H8: =IF((G8-F8) > 0, 0,G8-F8) -> 0
D9: 322041 | E9: Salatschale Schinken & Käse 4*300g | F9: =Overview!Q5 -> 0 | G9: =SUMIF($A$14:$A$175,D9,$C$14:$C$175) -> 0 | H9: =IF((G9-F9) > 0, 0,G9-F9) -> 0
D10: 322039 | E10: Salatschale Caesar 4*300g | F10: =Overview!Q6 -> 0 | G10: =SUMIF($A$14:$A$175,D10,$C$14:$C$175) -> 0 | H10: =IF((G10-F10) > 0, 0,G10-F10) -> 0
D11: 322040 | E11: Salatschale Hänchensalat mit Senf-Dressing 4*300g | F11: =Overview!Q7 -> 0 | G11: =SUMIF($A$14:$A$175,D11,$C$14:$C$175) -> 0 | H11: =IF((G11-F11) > 0, 0,G11-F11) -> 0
D12: 322014 | E12: Salatschale Hänchensalat mit Sylter-ArtDressing 4*300g | F12: =Overview!Q9 -> 0 | G12: =SUMIF($A$14:$A$175,D12,$C$14:$C$175) -> 0 | H12: =IF((G12-F12) > 0, 0,G12-F12) -> 0
D13: 322032 | E13: Mixkarton Rbg Chin en Ital NETTO 4*400g | F13: =Overview!Q8 -> 0 | G13: =SUMIF($A$14:$A$175,D13,$C$14:$C$175) -> 0 | H13: =IF((G13-F13) > 0, 0,G13-F13) -> 0

Sheet data_cache
A1: Warning! Do not edit or delete this worksheet! You may hide this worksheet, and it will no longer appear after the February 2016 Office update is installed.
A2: Column1 | B2: Column2 | D2: Column1
A3: WarehouseOnHand | B3: 0 | D3: {"ItemNumber":"10001","ProductName":"Sugarsnaps kg","InventoryWarehouseId":"GR","OnHandQuantity":1061.5,"TotalAvailableQuantity":1961.5,"AvailableOnHandQuantity":1061.5,"InventorySiteId":"VEN","dataAreaId":"hgv","ProductColorId":"","ProductConfigurationId":"","ProductSizeId":"","ProductStyleId":""}
D4: {"ItemNumber":"10003","ProductName":"Bieten B gekookt geschild kg","InventoryWarehouseId":"GR","OnHandQuantity":0,"TotalAvailableQuantity":375,"AvailableOnHandQuantity":0,"InventorySiteId":"VEN","dataAreaId":"hgv","ProductColorId":"","ProductConfigurationId":"","ProductSizeId":"","ProductStyleId":""}
D5: {"ItemNumber":"10004","ProductName":"BIO Boerenkool kg","InventoryWarehouseId":"GR","OnHandQuantity":1280,"TotalAvailableQuantity":1331.5,"AvailableOnHandQuantity":1280,"InventorySiteId":"VEN","dataAreaId":"hgv","ProductColorId":"","ProductConfigurationId":"","ProductSizeId":"","ProductStyleId":""}
D6: {"ItemNumber":"10010","ProductName":"Chinese kool kg","InventoryWarehouseId":"GR","OnHandQuantity":2178,"TotalAvailableQuantity":4978,"AvailableOnHandQuantity":2178,"InventorySiteId":"VEN","dataAreaId":"hgv","ProductColorId":"","ProductConfigurationId":"","ProductSizeId":"","ProductStyleId":""}
D7: {"ItemNumber":"10013","ProductName":"Groene kool kg","InventoryWarehouseId":"GR","OnHandQuantity":133,"TotalAvailableQuantity":133,"AvailableOnHandQuantity":133,"InventorySiteId":"VEN","dataAreaId":"hgv","ProductColorId":"","ProductConfigurationId":"","ProductSizeId":"","ProductStyleId":""}
D8: {"ItemNumber":"10015","ProductName":"Rode kool heel kg","InventoryWarehouseId":"GR","OnHandQuantity":5239,"TotalAvailableQuantity":30739,"AvailableOnHandQuantity":5239,"InventorySiteId":"VEN","dataAreaId":"hgv","ProductColorId":"","ProductConfigurationId":"","ProductSizeId":"","ProductStyleId":""}
D9: {"ItemNumber":"10017","ProductName":"Uien rood geschoond kg","InventoryWarehouseId":"GR","OnHandQuantity":14475.8,"TotalAvailableQuantity":77218.22,"AvailableOnHandQuantity":14475.8,"InventorySiteId":"VEN","dataAreaId":"hgv","ProductColorId":"","ProductConfigurationId":"","ProductSizeId":"","ProductStyleId":""}
D10: {"ItemNumber":"10018","ProductName":"Spitskool kg HSV","InventoryWarehouseId":"GR","OnHandQuantity":61636,"TotalAvailableQuantity":140103.031,"AvailableOnHandQuantity":61636,"InventorySiteId":"VEN","dataAreaId":"hgv","ProductColorId":"","ProductConfigurationId":"","ProductSizeId":"","ProductStyleId":""}
D11: {"ItemNumber":"10019","ProductName":"Peen gekopt (B peen) Oranje kg","InventoryWarehouseId":"GR","OnHandQuantity":1627,"TotalAvailableQuantity":14427,"AvailableOnHandQuantity":1627,"InventorySiteId":"VEN","dataAreaId":"hgv","ProductColorId":"","ProductConfigurationId":"","ProductSizeId":"","ProductStyleId":""}
D12: {"ItemNumber":"10020","ProductName":"Bieslook kg","InventoryWarehouseId":"GR","OnHandQuantity":12,"TotalAvailableQuantity":12,"AvailableOnHandQuantity":12,"InventorySiteId":"VEN","dataAreaId":"hgv","ProductColorId":"","ProductConfigurationId":"","ProductSizeId":"","ProductStyleId":""}
D13: {"ItemNumber":"10023","ProductName":"Paksoi kg","InventoryWarehouseId":"GR","OnHandQuantity":3552,"TotalAvailableQuantity":12552,"AvailableOnHandQuantity":3552,"InventorySiteId":"VEN","dataAreaId":"hgv","ProductColorId":"","ProductConfigurationId":"","ProductSizeId":"","ProductStyleId":""}
D14: {"ItemNumber":"10024","ProductName":"Bosui kg (Lente Ui)","InventoryWarehouseId":"GR","OnHandQuantity":252,"TotalAvailableQuantity":935.88,"AvailableOnHandQuantity":252,"InventorySiteId":"VEN","dataAreaId":"hgv","ProductColorId":"","ProductConfigurationId":"","ProductSizeId":"","ProductStyleId":""}
D15: {"ItemNumber":"10025","ProductName":"Frisee kg","InventoryWarehouseId":"GR","OnHandQuantity":4326,"TotalAvailableQuantity":26463,"AvailableOnHandQuantity":4326,"InventorySiteId":"VEN","dataAreaId":"hgv","ProductColorId":"","ProductConfigurationId":"","ProductSizeId":"","ProductStyleId":""}
... D3527: {"ItemNumber":"888","ProductName":"Doos Salat 2 tbv SS 380x190x144","InventoryWarehouseId":"EP","OnHandQuantity":18736,"TotalAvailableQuantity":34936,"AvailableOnHandQuantity":18736,"InventorySiteId":"VEN","dataAreaId":"hgv","ProductColorId":"","ProductConfigurationId":"","ProductSizeId":"","ProductStyleId":""}
